Workbook

Sheet PT1-By Year
A3: Row Labels | B3: Count of Matric No
A4: 2021-2022 | B4: 3933
A5: 2022-2023 | B5: 3784
A6: 2023-2024 | B6: 3775
A8: Grand Total | B8: 11492

Sheet PT2 - By Faculty
A3: Row Labels | B3: Count of Matric No
A4: Arts | B4: 1816
A5: Science | B5: 1744
A6: Education | B6: 1717
A7: Technology | B7: 1380
A8: The Social Sciences | B8: 674
A9: Agriculture | B9: 600
A10: College | B10: 600
A11: Clinical Sciences | B11: 520
A12: Law | B12: 443
A13: Basic Medical Sciences | B13: 369
A14: Grand Total | B14: 9863

Sheet PT3 - Gender by Faculty
A3: Count of Matric No | B3: Column Labels
A4: Row Labels | B4: Female | C4: Male | D4: Grand Total
A5: Agriculture | B5: 298 | C5: 302 | D5: 600
A6: Arts | B6: 1128 | C6: 688 | D6: 1816
A7: Basic Medical Sciences | B7: 131 | C7: 238 | D7: 369
A8: Clinical Sciences | B8: 208 | C8: 312 | D8: 520
A9: College | B9: 338 | C9: 262 | D9: 600
A10: Dentistry | B10: 20 | C10: 37 | D10: 57
A11: Economics and Management Sciences | B11: 119 | C11: 102 | D11: 221
A12: Education | B12: 1091 | C12: 626 | D12: 1717
A13: Law | B13: 244 | C13: 199 | D13: 443
A14: Pharmacy | B14: 124 | C14: 205 | D14: 329
A15: Grand Total | B15: 3701 | C15: 2971 | D15: 6672

Sheet PT4 - Dept by Year
A3: Count of Matric No | B3: Column Labels
A4: Row Labels | B4: 2021-2022 | C4: 2022-2023 | D4: 2023-2024 | E4: (blank) | F4: Grand Total
A5: Accounting | D5: 23 | F5: 23
A6: Adult Education | B6: 61 | C6: 43 | D6: 40 | F6: 144
A7: Agricultural and Environmental Engineering | B7: 63 | C7: 63 | D7: 59 | F7: 185
A8: Agricultural Economics | B8: 43 | C8: 38 | D8: 37 | F8: 118
A9: Agricultural Extension and Rural Development | B9: 46 | C9: 30 | D9: 27 | F9: 103
A10: Agriculture | D10: 1 | F10: 1
A11: Agronomy | B11: 41 | F11: 41
A12: Animal Science | B12: 52 | C12: 48 | D12: 55 | F12: 155
A13: Anthropology | B13: 62 | C13: 56 | D13: 52 | F13: 170
A14: Aquaculture and Fisheries Management | B14: 41 | C14: 33 | D14: 20 | F14: 94
A15: Arabic Language | B15: 8 | F15: 8
A16: Arabic Language and Literature | C16: 14 | D16: 15 | F16: 29
A17: Archaeology | C17: 34 | D17: 32 | F17: 66
A18: Archaeology (Arts) | B18: 28 | F18: 28
A19: Archaeology (Science) | B19: 9 | F19: 9
A20: Architecture | B20: 24 | C20: 28 | D20: 28 | F20: 80
A21: Arts & Social Sciences Education (Edu/Ara) | C21: 7 | F21: 7
A22: Arts & Social Sciences Education (Edu/CLA) | C22: 24 | F22: 24
A23: Arts & Social Sciences Education (Edu/Eco) | C23: 22 | F23: 22
A24: Arts & Social Sciences Education (Edu/Eng) | C24: 33 | F24: 33
A25: Arts & Social Sciences Education (Edu/Fre) | C25: 15 | F25: 15
A26: Arts & Social Sciences Education (Edu/His) | C26: 15 | F26: 15
A27: Arts & Social Sciences Education (Edu/IRS) | C27: 12 | F27: 12
A28: Arts & Social Sciences Education (Edu/Pos) | C28: 33 | F28: 33
A29: Arts & Social Sciences Education (Edu/Res) | C29: 13 | F29: 13
A30: Arts & Social Sciences Education (Edu/Yor) | C30: 3 | F30: 3
A31: Banking and Finance | D31: 22 | F31: 22
A32: Biochemistry | B32: 79 | C32: 65 | D32: 68 | F32: 212
A33: Botany | B33: 58 | C33: 57 | D33: 53 | F33: 168
A34: Business Education | C34: 25 | D34: 18 | F34: 43
A35: Chemistry | B35: 63 | C35: 63 | D35: 76 | F35: 202
A36: Chemistry | C36: 3 | F36: 3
A37: Christian Religious Studies | B37: 13 | F37: 13
A38: Civil Engineering | B38: 67 | C38: 67 | D38: 59 | F38: 193
A39: Classical Studies | C39: 43 | D39: 47 | F39: 90
A40: Classics | B40: 46 | F40: 46
A41: Communication and Language Arts | B41: 66 | C41: 67 | D41: 70 | F41: 203
A42: Communication and Language Arts Education | B42: 23 | D42: 35 | F42: 58
...

Sheet Dashboard
A1: UNIVERSITY OF IBADAN ENROLLMENT DASHBOARD (2021-2024)

Sheet Raw Data
A1: Matric No | B1: Name | C1: gender | D1: state | E1: LG | F1: jamb score | G1: utme | H1: aggreg | I1: Faculty | J1: Department | K1: Year
A2: 228268 | B2: Adebayo Maryam Awero | C2: Female | D2: OYO | E2: AKINYELE | F2: 291 | G2: 63 | H2: 67.875 | I2: Agriculture | J2: Agricultural Economics | K2: 2021-2022
A3: 228269 | B3: Adedara Gbemisola Victoria | C3: Female | D3: EKITI | E3: EKITI-SOUTH-WEST | F3: 245 | G3: 63 | H3: 62.125 | I3: Agriculture | J3: Agricultural Economics | K3: 2021-2022
A4: 228270 | B4: Adegbesan Oluwadamilola Abodunrin | C4: Male | D4: OGUN | E4: IJEBU-NORTH | F4: 260 | G4: 60 | H4: 62.5 | I4: Agriculture | J4: Agricultural Economics | K4: 2021-2022
A5: 228271 | B5: Adeleye Happiness Temidayo | C5: Female | D5: OGUN | E5: ABEOKUTA-NORTH | F5: 255 | G5: 63 | H5: 63.375 | I5: Agriculture | J5: Agricultural Economics | K5: 2021-2022
A6: 228272 | B6: Adenaike Sheriffdeen Eniola | C6: Male | D6: OGUN | E6: IJEBU-NORTH | F6: 238 | G6: 56 | H6: 57.75 | I6: Agriculture | J6: Agricultural Economics | K6: 2021-2022
A7: 228273 | B7: Adewusi Basit Ayobami | C7: Male | D7: OYO | E7: IBADAN CENTRAL | F7: 201 | G7: 56 | H7: 53.125 | I7: Agriculture | J7: Agricultural Economics | K7: 2021-2022
A8: 228274 | B8: Adigwe Deborah Chioma | C8: Female | D8: DELTA | E8: ANIOCHA SOUTH | F8: 213 | G8: 52 | H8: 52.625 | I8: Agriculture | J8: Agricultural Economics | K8: 2021-2022
A9: 228275 | B9: Agboola Joshua Oluwaseun | C9: Male | D9: OSUN | E9: IFE-EAST | F9: 265 | G9: 56 | H9: 61.125 | I9: Agriculture | J9: Agricultural Economics | K9: 2021-2022
A10: 228276 | B10: Ajimatokin Anthony Bamidele | C10: Male | D10: ONDO | E10: IRELE | F10: 247 | G10: 56 | H10: 58.875 | I10: Agriculture | J10: Agricultural Economics | K10: 2021-2022
A11: 228277 | B11: Aliu Ibrahim Olakunle | C11: Male | D11: KWARA | E11: IREPODUN | F11: 233 | G11: 58 | H11: 58.125 | I11: Agriculture | J11: Agricultural Economics | K11: 2021-2022
A12: 228278 | B12: Aniobia Victor Oluwaseyi | C12: Male | D12: DELTA | E12: NDOKWA-WEST | F12: 273 | G12: 65 | H12: 66.625 | I12: Agriculture | J12: Agricultural Economics | K12: 2021-2022
A13: 228279 | B13: Ashimiyu Temitope Simbiat | C13: Female | D13: OYO | E13: IBADAN NORTH EAST | F13: 257 | G13: 51 | H13: 57.625 | I13: Agriculture | J13: Agricultural Economics | K13: 2021-2022
A14: 228280 | B14: ASIMIYU JELEEL KEHINDE | C14: Male | D14: OSUN | E14: IWO | F14: Agric Technology | G14: 17 | H14: U/C | I14: Agriculture | J14: Agricultural Economics | K14: 2021-2022
A15: 228281 | B15: Asimolowo Semilogo Ayo | C15: Male | D15: OSUN | E15: ILESHA-WEST | F15: 260 | G15: 56 | H15: 60.5 | I15: Agriculture | J15: Agricultural Economics | K15: 2021-2022
A16: 228282 | B16: Atobatele Ayomide Damilola | C16: Female | D16: OSUN | E16: ORIADE | F16: 252 | G16: 57 | H16: 60 | I16: Agriculture | J16: Agricultural Economics | K16: 2021-2022
A17: 228283 | B17: Ayeni Oluwatofunmi Ruth | C17: Female | D17: OSUN | E17: ORIADE | F17: 236 | G17: 51 | H17: 55 | I17: Agriculture | J17: Agricultural Economics | K17: 2021-2022
A18: 228284 | B18: AYINDE EBUNOLUWA TEMILEYIN | C18: Female | D18: OYO | E18: AKINYELE | F18: Agric Technology | G18: 19 | H18: DIST | I18: Agriculture | J18: Agricultural Economics | K18: 2021-2022
A19: 228285 | B19: Badmas Aminat Bamidele | C19: Female | D19: OYO | E19: IDO | F19: 234 | G19: 51 | H19: 54.75 | I19: Agriculture | J19: Agricultural Economics | K19: 2021-2022
A20: 228286 | B20: Bolaji Ayomide | C20: Male | D20: EKITI | E20: IKOLE | F20: 250 | G20: 62 | H20: 62.25 | I20: Agriculture | J20: Agricultural Economics | K20: 2021-2022
A21: 228287 | B21: Chukwu Joseph Sunday | C21: Male | D21: ABIA | E21: BENDE | F21: 253 | G21: 61 | H21: 62.125 | I21: Agriculture | J21: Agricultural Economics | K21: 2021-2022
A22: 228288 | B22: Fagade Oluwafemi Theophilus | C22: Male | D22: OYO | E22: LAGELU | F22: 218 | G22: 55 | H22: 54.75 | I22: Agriculture | J22: Agricultural Economics | K22: 2021-2022
A23: 228289 | B23: Falade John Blessing | C23: Male | D23: EKITI | E23: ADO-EKITI | F23: 258 | G23: 59 | H23: 61.75 | I23: Agriculture | J23: Agricultural Economics | K23: 2021-2022
A24: 228290 | B24: Ibrahim Esther Olajumoke | C24: Female | D24: KOGI | E24: OKENE | F24: 297 | G24: 61 | H24: 67.625 | I24: Agriculture | J24: Agricultural Economics | K24: 2021-2022
A25: 228291 | B25: JAMES OLANIYI JOSHUA | C25: Male | D25: OYO | E25: IBADAN NORTH EAST | F25: Agric Technology | G25: 17 | H25: U/C | I25: Agriculture | J25: Agricultural Economics | K25: 2021-2022
A26: 228292 | B26: Jegede Senior Oluwatumininu | C26: Male | D26: OSUN | E26: ILESHA-WEST | F26: 261 | G26: 56 | H26: 60.625 | I26: Agriculture | J26: Agricultural Economics | K26: 2021-2022
A27: 228293 | B27: KILANKO TIMILEYIN JOSHUA | C27: Male | D27: OYO | E27: EGBEDA | F27: Agric Technology | G27: 15 | H27: DIST | I27: Agriculture | J27: Agricultural Economics | K27: 2021-2022
A28: 228294 | B28: Lawal Abdurrahman Olawale | C28: Male | D28: OGUN | E28: ABEOKUTA-NORTH | F28: 237 | G28: 50 | H28: 54.625 | I28: Agriculture | J28: Agricultural Economics | K28: 2021-2022
A29: 228295 | B29: Lawal Quayyum Adedolapo | C29: Male | D29: LAGOS | E29: MUSHIN | F29: 243 | G29: 53 | H29: 56.875 | I29: Agriculture | J29: Agricultural Economics | K29: 2021-2022
A30: 228296 | B30: Obinwa Destiny Kosisochukwu | C30: Female | D30: ANAMBRA | E30: IDEMILI-NORTH | F30: 210 | G30: 54 | H30: 53.25 | I30: Agriculture | J30: Agricultural Economics | K30: 2021-2022
A31: 228297 | B31: Ogbodo Elvis Somunachi | C31: Male | D31: ENUGU | E31: UDI | F31: 273 | G31: 60 | H31: 64.125 | I31: Agriculture | J31: Agricultural Economics | K31: 2021-2022
A32: 228298 | B32: Ogunsanwo Adedotun Feranmi | C32: Male | D32: OGUN | E32: IJEBU-NORTH | F32: 244 | G32: 57 | H32: 59 | I32: Agriculture | J32: Agricultural Economics | K32: 2021-2022
A33: 228299 | B33: Olayiwola Doyinsola Aishat | C33: Female | D33: OYO | E33: EGBEDA | F33: 257 | G33: 52 | H33: 58.125 | I33: Agriculture | J33: Agricultural Economics | K33: 2021-2022
A34: 228300 | B34: OLORUNTOBA MARY IBITOLA | C34: Female | D34: ONDO | E34: AKOKO-SOUTH | F34: Fisheries Technology | G34: 18 | H34: DIST | I34: Agriculture | J34: Agricultural Economics | K34: 2021-2022
A35: 228301 | B35: Olujemibola Oluwatimileyin O | C35: Male | D35: EKITI | E35: OYE | F35: 238 | G35: 52 | H35: 55.75 | I35: Agriculture | J35: Agricultural Economics | K35: 2021-2022
A36: 228302 | B36: Oluwadare Oluwatoberu Peter | C36: Male | D36: EKITI | E36: EKITI-WEST | F36: 287 | G36: 50 | H36: 60.875 | I36: Agriculture | J36: Agricultural Economics | K36: 2021-2022
A37: 228303 | B37: Oluyomi David Olanrewajutete | C37: Male | D37: OGUN | E37: IJEBU-ODE | F37: 255 | G37: 51 | H37: 57.375 | I37: Agriculture | J37: Agricultural Economics | K37: 2021-2022
A38: 228304 | B38: Omotilewa Adunola Omobonike | C38: Female | D38: OGUN | E38: ABEOKUTA-SOUTH | F38: 245 | G38: 60 | H38: 60.625 | I38: Agriculture | J38: Agricultural Economics | K38: 2021-2022
A39: 228305 | B39: OYEBAMIJI MARIAM OYELADUN | C39: Female | D39: OYO | E39: IDO | F39: Agric Technology | G39: 16 | H39: DIST | I39: Agriculture | J39: Agricultural Economics | K39: 2021-2022
A40: 228306 | B40: Oyedoyin Ayomide Emmanuel | C40: Male | D40: OYO | E40: EGBEDA | F40: 275 | G40: 65 | H40: 66.875 | I40: Agriculture | J40: Agricultural Economics | K40: 2021-2022
...

Sheet Summary Stats
A1: ENROLLMENT SUMMARY STATISTICS (2023-2024)
A4: Total Students | B4: =COUNTA('Raw Data'!A:A)-1 -> 11492
A5: Total Male Students | B5: =COUNTIF('Raw Data'!C:C,"Male") -> 5968
A6: Total Female Students | B6: =COUNTIF('Raw Data'!C:C,"Female") -> 5525
A7: Male Percentage | B7: =B5/B4*100 -> 51.931779
A8: Female Percentage | B8: =B6/B4*100 -> 48.076923
A10: STUDENTS PER YEAR
A11: 2021-2022 | B11: =COUNTIF('Raw Data'!K:K,"2021-2022") -> 3933
A12: 2022-2023 | B12: =COUNTIF('Raw Data'!K:K,"2022-2023") -> 3784
A13: 2023-2024 | B13: =COUNTIF('Raw Data'!K:K,"2023-2024") -> 3776
A15: DATE RANGE
A16: First Year | B16: =COUNTIF('Raw Data'!K2:K11494, "*2021-2022*") -> 3933
A17: Last Year | B17: =COUNTIF('Raw Data'!K2:K11494, "*2023-2024*") -> 3776
A18: Years Covered | B18: 3
A20: SCORE STATISTICS
A21: Average Jamb Score | B21: =AVERAGE('Raw Data'!F:F) -> 257.55015
A22: Highest Jamb Score | B22: =MAX('Raw Data'!F:F) -> 355
A23: Lowest Jamb Score | B23: =MIN('Raw Data'!F:F) -> 0
A24: Average PostUtme | B24: =AVERAGE('Raw Data'!G:G) -> 58.94105
A25: Highest PostUtme | B25: =MAX('Raw Data'!G:G) -> 95
A26: Lowest PostUtme | B26: =MIN('Raw Data'!G:G) -> 0
A28: FACULTY BREAKDOWN
B29: Students | C29: Percentage
A30: Agriculture | B30: =COUNTIF('Raw Data'!I:I,"Agriculture")+COUNTIF('Raw Data'!I:I,"agriculture") -> 1200 | C30: =(B30/$B$4)*100 -> 10.442047
A31: Arts | B31: =COUNTIF('Raw Data'!I:I,"Arts")+COUNTIF('Raw Data'!I:I,"ARTS") -> 3632 | C31: =(B31/$B$4)*100 -> 31.604595
A32: Basic Medical Sciences | B32: =COUNTIF('Raw Data'!I:I,"Basic Medical Sciences") -> 369 | C32: =(B32/$B$4)*100 -> 3.2109293
A33: Clinical Sciences | B33: =COUNTIF('Raw Data'!I:I,"Clinical Sciences") -> 520 | C33: =(B33/$B$4)*100 -> 4.5248869
A34: College | B34: =COUNTIF('Raw Data'!I:I,"College") -> 601 | C34: =(B34/$B$4)*100 -> 5.229725
A35: Dentistry | B35: =COUNTIF('Raw Data'!I:I,"Dentistry") -> 57 | C35: =(B35/$B$4)*100 -> 0.49599722
A36: Economics & Management Sciences | B36: =COUNTIF('Raw Data'!I:I,"Economics & Management Sciences")+COUNTIF('Raw Data'!I:I,"Economics and Management Sciences") -> 299 | C36: =(B36/$B$4)*100 -> 2.60181
A37: Education | B37: =COUNTIF('Raw Data'!I:I,"Education") -> 1717 | C37: =(B37/$B$4)*100 -> 14.940828
A38: Environmental Design & Management | B38: =COUNTIF('Raw Data'!I:I,"Environmental Design & Management")+COUNTIF('Raw Data'!I:I,"Environmental Design Management") -> 163 | C38: =(B38/$B$4)*100 -> 1.418378
A39: Law | B39: =COUNTIF('Raw Data'!I:I,"Law") -> 443 | C39: =(B39/$B$4)*100 -> 3.8548556
A40: Pharmacy | B40: =COUNTIF('Raw Data'!I:I,"Pharmacy") -> 329 | C40: =(B40/$B$4)*100 -> 2.8628611
A41: Public Health | B41: =COUNTIF('Raw Data'!I:I,"Public Health") -> 215 | C41: =(B41/$B$4)*100 -> 1.8708667
A42: Renewable Natural Resources | B42: =COUNTIF('Raw Data'!I:I,"Renewable Natural Resources") -> 273 | C42: =(B42/$B$4)*100 -> 2.3755656
A43: Science | B43: =COUNTIF('Raw Data'!I:I,"Science") -> 1744 | C43: =(B43/$B$4)*100 -> 15.175774
A44: Technology | B44: =COUNTIF('Raw Data'!I:I,"Technology") -> 1380 | C44: =(B44/$B$4)*100 -> 12.008354
A45: The Social Sciences | B45: =COUNTIF('Raw Data'!I:I,"The Social Sciences") -> 674 | C45: =(B45/$B$4)*100 -> 5.8649495
A46: Veterinary Medicine | B46: =COUNTIF('Raw Data'!I:I,"Veterinary Medicine") -> 289 | C46: =(B46/$B$4)*100 -> 2.5147929
